Workbook

Sheet New Riyadh Regions
A1: Number | B1: District Name in English | C1: New Region | D1: Done | E1: Need to be checked | F1: Empty based on google map | G1: Comments | H1: Population
A2: 1 | B2: Al Ezdihar | C2: Center | D2: Yes | H2: 35507
A3: 2 | B3: Al Taawun | C3: Center | D3: Yes | H3: 49965
A4: 3 | B4: Al Maseef | C4: Center | D4: Yes | H4: 42594
A5: 4 | B5: Al Muruj | C5: Center | D5: Yes | H5: 39391
A6: 5 | B6: Al Mughrazat | C6: Center | D6: Yes | H6: 16460
A7: 6 | B7: Al Nuzha | C7: Center | D7: Yes | H7: 27415
A8: 7 | B8: Al Mursalat | C8: Center | D8: Yes | H8: 20338
A9: 8 | B9: King Fahd | C9: Center | D9: Yes | H9: 34511
A10: 9 | B10: King Abdullah | C10: Center | D10: Yes | H10: 17697
A11: 10 | B11: King Salman | C11: Center | D11: Yes | G11: Al Wahah and Salahuddin previously | H11: 26336
A12: 11 | B12: Al Woroud | C12: Center | D12: Yes | H12: 39241
A13: 12 | B13: King Abdulaziz | C13: Center | D13: Yes | H13: 55187
A14: 13 | B14: Al Sulaimaniyah | C14: Center | D14: Yes | H14: 90252
A15: 14 | B15: Al Olaya | C15: Center | D15: Yes | H15: 118753
A16: 15 | B16: Ar Rabwah | C16: Center | D16: Yes | H16: 70591
A17: 16 | B17: Al Zahra | C17: Center | D17: Yes | H17: 18684
A18: 17 | B18: Al Malaz | C18: Center | D18: Yes | H18: 93066
A19: 18 | B19: Al Wizarat | C19: Center | D19: Yes | H19: 65790
A20: 19 | B20: Jareer | C20: Center | D20: Yes | H20: 30972
A21: 20 | B21: Al Murabba | C21: Center | D21: Yes | H21: 58068
A22: 21 | B22: Al Futah | C22: Center | D22: Yes | H22: 15526
A23: 22 | B23: Al Amal | C23: Center | D23: Yes | H23: 20513
... A94: 93 | B94: Al Nadwah | C94: East | D94: Yes | H94: 43383
A95: 94 | B95: Al Basatin | C95: East | D95: Yes | G95: Includes Dhahyat Al Fursan | H95: 0
A96: 95 | B96: Al Falah | C96: North | D96: Yes | H96: 24782
A97: 96 | B97: Al Nafel | C97: North | D97: Yes | H97: 49438
A98: 97 | B98: Al Ghadeer | C98: North | D98: Yes | H98: 21308
A99: 98 | B99: Al Aqeeq | C99: North | D99: Yes | H99: 53471
A100: 99 | B100: Hiteen | C100: North | D100: Yes | H100: 35795
A101: 100 | B101: Al Malqa | C101: North | D101: Yes | H101: 87931
A102: 101 | B102: Al Sahafah | C102: North | D102: Yes | H102: 52135
A103: 102 | B103: Ar Rabie | C103: North | D103: Yes | H103: 35054
A104: 103 | B104: Al Nada | C104: North | D104: Yes | H104: 19017
A105: 104 | B105: Al Yasmeen | C105: North | D105: Yes | H105: 107229
A106: 105 | B106: Imam Muhammed Bin Saud Islamic University | C106: North | D106: Yes | H106: 6241
A107: 106 | B107: Al Narjis | C107: North | D107: Yes | H107: 82800
... A113: 112 | B113: Sedrah | C113: East | D113: Yes | H113: 0
A114: 113 | B114: King Khalid International Airport | C114: North | D114: Yes | G114: Includes Dhahyat Al Khuzam | H114: 17031
A115: 114 | B115: East Naseem | C115: South | D115: Yes | H115: 139943
...

Sheet List
A1: Number | B1: District Name in English | C1: New Region | D1: name_en | E1: Done (Yes or No) | F1: Need to be checked (Yes or No) | G1: Empty based on google map (Yes or No) | H1: Comments
A2: 50 | B2: Al Rayah | C2: =VLOOKUP(B2, [1]Sheet2!C:D, 2, FALSE) -> East | D2: Al Rayah | E2: No | F2: No | G2: Yes
A3: 51 | B3: Al Basatin | C3: =VLOOKUP(B3, [1]Sheet2!C:D, 2, FALSE) -> East | D3: Al Basatin | E3: No | F3: No | G3: Yes | H3: Includes Dhahyat Al Fursan
A4: 52 | B4: Al Sholah | C4: =VLOOKUP(B4, [1]Sheet2!C:D, 2, FALSE) -> East | D4: Al Sholah | E4: No | F4: No | G4: Yes
A5: 53 | B5: Al Zaher | C5: =VLOOKUP(B5, [1]Sheet2!C:D, 2, FALSE) -> East | D5: Al Zaher | E5: No | F5: No | G5: Yes
A6: 54 | B6: Al Zahour | C6: =VLOOKUP(B6, [1]Sheet2!C:D, 2, FALSE) -> East | D6: Al Zahour | E6: No | F6: No | G6: Yes
A7: 55 | B7: Al Majd | C7: =VLOOKUP(B7, [1]Sheet2!C:D, 2, FALSE) -> East | D7: Al Majd | E7: No | F7: No | G7: Yes
A8: 56 | B8: Al Risalah | C8: =VLOOKUP(B8, [1]Sheet2!C:D, 2, FALSE) -> East | D8: Al Risalah | E8: No | F8: No | G8: Yes
A9: 57 | B9: Al Ula | C9: =VLOOKUP(B9, [1]Sheet2!C:D, 2, FALSE) -> East | D9: Al Ula | E9: No | F9: No | G9: Yes
A10: 58 | B10: Al Danah | C10: =VLOOKUP(B10, [1]Sheet2!C:D, 2, FALSE) -> East | D10: Al Danah | E10: No | F10: No | G10: Yes
A11: 59 | B11: Al Nakhbah | C11: =VLOOKUP(B11, [1]Sheet2!C:D, 2, FALSE) -> East | D11: Al Nakhbah | E11: No | F11: No | G11: Yes
A12: 60 | B12: Al Bashaer | C12: =VLOOKUP(B12, [1]Sheet2!C:D, 2, FALSE) -> East | D12: Al Bashaer | E12: No | F12: No | G12: Yes
A13: 61 | B13: Al Mashriq | C13: =VLOOKUP(B13, [1]Sheet2!C:D, 2, FALSE) -> East | D13: Al Mashriq | E13: No | F13: No | G13: Yes
A14: 62 | B14: Al Wasam | C14: =VLOOKUP(B14, [1]Sheet2!C:D, 2, FALSE) -> East | D14: Al Wasam | E14: No | F14: No | G14: Yes
A15: 63 | B15: Al Sahab | C15: =VLOOKUP(B15, [1]Sheet2!C:D, 2, FALSE) -> East | D15: Al Sahab | E15: No | F15: No | G15: Yes
... A23: 151 | B23: King Abdullah City For Energy | C23: =VLOOKUP(B23, [1]Sheet2!C:D, 2, FALSE) -> West | D23: King Abdullah City For Energy | E23: No | F23: No | G23: Yes
A24: 190 | B24: Asehbaa | C24: =VLOOKUP(B24, [1]Sheet2!C:D, 2, FALSE) -> South | D24: Asehbaa | E24: No | F24: No | G24: Yes | H24: A separate district but part of Al Haer
A25: 1 | B25: Al Faisaliyah | C25: =VLOOKUP(B25, [1]Sheet2!C:D, 2, FALSE) -> Center | D25: Al Faisaliyah | E25: No | F25: Yes | G25: No
A26: 2 | B26: Al Sinaiyah | C26: =VLOOKUP(B26, [1]Sheet2!C:D, 2, FALSE) -> Center | D26: Al Sinaiyah | E26: No | F26: Yes | G26: No
A27: 3 | B27: Al Khalidiyah | C27: =VLOOKUP(B27, [1]Sheet2!C:D, 2, FALSE) -> Center | D27: Al Khalidiyah | E27: No | F27: Yes | G27: No
A28: 4 | B28: Al Butaiha | C28: =VLOOKUP(B28, [1]Sheet2!C:D, 2, FALSE) -> Center | D28: Al Butaiha | E28: No | F28: Yes | G28: No
A29: 49 | B29: Al Nadwah | C29: =VLOOKUP(B29, [1]Sheet2!C:D, 2, FALSE) -> East | D29: Al Nadwah | E29: No | F29: Yes | G29: No
A30: 100 | B30: Sedrah | C30: =VLOOKUP(B30, [1]Sheet2!C:D, 2, FALSE) -> East | D30: Sedrah | E30: No | F30: Yes | G30: No
A31: 101 | B31: King Khalid International Airport | C31: =VLOOKUP(B31, [1]Sheet2!C:D, 2, FALSE) -> North | D31: King Khalid International Airport | E31: No | F31: Yes | G31: No | H31: Includes Dhahyat alkhuzam
A32: 144 | B32: Al Zahrah | C32: =VLOOKUP(B32, [1]Sheet2!C:D, 2, FALSE) -> West | D32: Al Zahrah | E32: No | F32: Yes | G32: No
A33: 145 | B33: King Saud University | C33: =VLOOKUP(B33, [1]Sheet2!C:D, 2, FALSE) -> Center | D33: King Saud University | E33: No | F33: Yes | G33: No
A34: 146 | B34: Dirab | C34: =VLOOKUP(B34, [1]Sheet2!C:D, 2, FALSE) -> West | D34: Dirab | E34: No | F34: Yes | G34: No
A35: 147 | B35: Tuwaiq | C35: =VLOOKUP(B35, [1]Sheet2!C:D, 2, FALSE) -> West | D35: Tuwaiq | E35: No | F35: Yes | G35: No
A36: 148 | B36: Al Mahdiyah | C36: =VLOOKUP(B36, [1]Sheet2!C:D, 2, FALSE) -> West | D36: Al Mahdiyah | E36: No | F36: Yes | G36: No
A37: 5 | B37: Al Ezdihar | C37: =VLOOKUP(B37, [1]Sheet2!C:D, 2, FALSE) -> Center | D37: Al Ezdihar | E37: Yes
A38: 6 | B38: Al Taawun | C38: =VLOOKUP(B38, [1]Sheet2!C:D, 2, FALSE) -> Center | D38: Al Taawun | E38: Yes
A39: 7 | B39: Al Maseef | C39: =VLOOKUP(B39, [1]Sheet2!C:D, 2, FALSE) -> Center | D39: Al Maseef | E39: Yes
A40: 8 | B40: Al Muruj | C40: =VLOOKUP(B40, [1]Sheet2!C:D, 2, FALSE) -> Center | D40: Al Muruj | E40: Yes
A41: 9 | B41: Al Mughrazat | C41: =VLOOKUP(B41, [1]Sheet2!C:D, 2, FALSE) -> Center | D41: Al Mughrazat | E41: Yes
A42: 10 | B42: Al Nuzha | C42: =VLOOKUP(B42, [1]Sheet2!C:D, 2, FALSE) -> Center | D42: Al Nuzha | E42: Yes
A43: 11 | B43: Al Mursalat | C43: =VLOOKUP(B43, [1]Sheet2!C:D, 2, FALSE) -> Center | D43: Al Mursalat | E43: Yes
A44: 12 | B44: King Fahd | C44: =VLOOKUP(B44, [1]Sheet2!C:D, 2, FALSE) -> Center | D44: King Fahd | E44: Yes
A45: 13 | B45: King Abdullah | C45: =VLOOKUP(B45, [1]Sheet2!C:D, 2, FALSE) -> Center | D45: King Abdullah | E45: Yes
A46: 14 | B46: King Salman | C46: =VLOOKUP(B46, [1]Sheet2!C:D, 2, FALSE) -> Center | D46: King Salman | E46: Yes | H46: Al Wahah and Salahuddin previously
A47: 15 | B47: Al Woroud | C47: =VLOOKUP(B47, [1]Sheet2!C:D, 2, FALSE) -> Center | D47: Al Woroud | E47: Yes
...

Sheet Distributed districts clean
A1: ID | B1: District in English | C1: Region | D1: Group A | E1: Group B | F1: Group C | G1: Group D | H1: Group E | I1: Group F | J1: Group G | K1: Round
A2: 1 | B2: Al Yasmeen | C2: North | D2: 1 | E2: 1 | F2: 1 | G2: 1 | H2: 1 | I2: 1 | J2: 1 | K2: 1
A3: 2 | B3: Al Narjis | C3: North | D3: 1 | E3: 1 | F3: 1 | G3: 1 | H3: 1 | I3: 1 | J3: 1 | K3: 1
A4: 3 | B4: Al Malqa | C4: North | D4: 1 | H4: 1 | K4: 2
A5: 4 | B5: Al Andalus | C5: East | D5: 1 | H5: 1 | K5: 2
A6: 5 | B6: Al Munisiyah | C6: East | E6: 1 | G6: 1 | K6: 2
A7: 6 | B7: Al Quds | C7: East | E7: 1 | G7: 1 | K7: 2
A8: 7 | B8: Hiteen | C8: North | F8: 1 | J8: 1 | K8: 2
A9: 8 | B9: Al Arid | C9: North | F9: 1 | J9: 1 | K9: 2
A10: 9 | B10: Al Hamra | C10: East | E10: 1 | G10: 1 | K10: 2
A11: 10 | B11: King Faisal | C11: East | E11: 1 | G11: 1 | K11: 2
A12: 11 | B12: Al Woroud | C12: Center | H12: 1 | I12: 1 | K12: 2
A13: 12 | B13: Ghirnatah | C13: East | H13: 1 | I13: 1 | K13: 2
A14: 13 | B14: Al Yarmuk | C14: East | D14: 1 | I14: 1 | K14: 2
A15: 14 | B15: Al Aqeeq | C15: North | D15: 1 | I15: 1 | K15: 2
A16: 15 | B16: Al Nuzha | C16: Center | F16: 1 | J16: 1 | K16: 2
A17: 16 | B17: Al Ghadeer | C17: North | F17: 1 | J17: 1 | K17: 2
A18: 17 | B18: Banban | C18: North | E18: 1 | K18: 3
A19: 18 | B19: Al Nada | C19: North | E19: 1 | K19: 3
A20: 19 | B20: Al Nadheem | C20: East | E20: 1 | K20: 3
A21: 20 | B21: Al Nadwah | C21: East | E21: 1 | K21: 3
A22: 21 | B22: Al Salam | C22: East | F22: 1 | K22: 3
A23: 22 | B23: Ar Rabie | C23: North | F23: 1 | K23: 3
A24: 23 | B24: Al Rayan | C24: East | G24: 1 | K24: 3
A25: 24 | B25: Al Falah | C25: North | G25: 1 | K25: 3
A26: 25 | B26: Al Nafel | C26: North | H26: 1 | K26: 3
A27: 26 | B27: Al Khair | C27: North | H27: 1 | K27: 3
A28: 27 | B28: Al Manar | C28: East | I28: 1 | K28: 3
A29: 28 | B29: Al Maizilah | C29: East | I29: 1 | K29: 3
A30: 29 | B30: Al Janadriyah | C30: East | J30: 1 | K30: 3
A31: 30 | B31: Al Rimayah | C31: East | J31: 1 | K31: 3
A32: 31 | B32: East Naseem | C32: East | E32: 1 | K32: 4
A33: 32 | B33: West Naseem | C33: East | E33: 1 | K33: 4
A34: 33 | B34: Al Shohda | C34: East | E34: 1 | H34: 1 | I34: 1 | K34: 4 | L34: Groups E and F went to Al Shohda as part of Ghirnatah in round 2
A35: 34 | B35: Al Rawdah | C35: East | F35: 1 | K35: 4
A36: 35 | B36: Al Bayan | C36: East | F36: 1 | K36: 4
A37: 36 | B37: Al Wadi | C37: North | F37: 1 | K37: 4
A38: 37 | B38: Al Nahdah | C38: East | G38: 1 | K38: 4
A39: 38 | B39: Ishbiliyah | C39: East | G39: 1 | K39: 4
A40: 39 | B40: Al Fayha | C40: East | G40: 1 | K40: 4
...

Sheet Random selection of streets
A1: ID | B1: District Number | C1: District in Arabic | D1: District in English | E1: Street | F1: Sampled for quality check | G1: Round | H1: Comments
A2: 1 | B2: 1 | C2: الياسمين | D2: Al Yasmeen | E2: طريق انس بن مالك | F2: 1 | G2: 1
A3: 2 | B3: 1 | C3: الياسمين | D3: Al Yasmeen | E3: طريق الملك عبدالعزيز جهة اليمين | F3: 1 | G3: 1
A4: 3 | B4: 1 | C4: الياسمين | D4: Al Yasmeen | E4: طريق أبي بكر الصديق جهة اليمين | F4: 1 | G4: 1
A5: 4 | B5: 1 | C5: الياسمين | D5: Al Yasmeen | E5: طريق الثمامة الفرعي | F5: 1 | G5: 1
A6: 5 | B6: 1 | C6: الياسمين | D6: Al Yasmeen | E6: طريق الملك فهد | F6: 1 | G6: 1
A7: 6 | B7: 1 | C7: الياسمين | D7: Al Yasmeen | E7: شارع القلعة | F7: 1 | G7: 1
A8: 7 | B8: 1 | C8: الياسمين | D8: Al Yasmeen | E8: شارع الفجر | F8: 1 | G8: 1
A9: 8 | B9: 1 | C9: الياسمين | D9: Al Yasmeen | E9: شارع القادسية | F9: 1 | G9: 1
A10: 9 | B10: 1 | C10: الياسمين | D10: Al Yasmeen | E10: شارع الأمير ناصر بن سعود بن فرحان آل سعود | F10: 1 | G10: 1
A11: 10 | B11: 1 | C11: الياسمين | D11: Al Yasmeen | E11: القنا | F11: 1 | G11: 1
A12: 11 | B12: 1 | C12: الياسمين | D12: Al Yasmeen | E12: الامير عبدالعزيز بن عياف | F12: 1 | G12: 1
A13: 12 | B13: 1 | C13: الياسمين | D13: Al Yasmeen | E13: الخيالة | F13: 1 | G13: 1
... A431: 430 | B431: 16 | C431: غرناطة | D431: Ghirnatah | E431: وادي الناقب | F431: 1 | G431: 2
A432: 431 | B432: 17 | C432: بنبان | D432: Banban | E432: طريق صلبوخ | G432: 3
A433: 432 | B433: 17 | C433: بنبان | D433: Banban | E433: طريق الملك خالد الفرعي | F433: 1 | G433: 3
A434: 433 | B434: 17 | C434: بنبان | D434: Banban | E434: SS21 Link | G434: 3
A435: 434 | B435: 17 | C435: بنبان | D435: Banban | E435: SS22 Link 2 | G435: 3
A436: 435 | B436: 17 | C436: بنبان | D436: Banban | E436: طريق الملك فهد | G436: 3
A437: 436 | B437: 17 | C437: بنبان | D437: Banban | E437: طريق الأمير محمد بن سعد بن عبدالعزيز | G437: 3
A438: 437 | B438: 17 | C438: بنبان | D438: Banban | E438: طريق بنبان | G438: 3
A439: 438 | B439: 17 | C439: بنبان | D439: Banban | E439: طريق بنبان المطار | G439: 3
A440: 439 | B440: 17 | C440: بنبان | D440: Banban | E440: وادي بنبان | G440: 3
A441: 440 | B441: 17 | C441: بنبان | D441: Banban | E441: شارع الماس | G441: 3
A442: 441 | B442: 17 | C442: بنبان | D442: Banban | E442: شارع خالد بن معبد | G442: 3
A443: 442 | B443: 17 | C443: بنبان | D443: Banban | E443: شارع الصواب | G443: 3
A444: 443 | B444: 17 | C444: بنبان | D444: Banban | E444: شارع الدرة | G444: 3
A445: 444 | B445: 17 | C445: بنبان | D445: Banban | E445: شارع الربيع الجرمي | F445: 1 | G445: 3
A446: 445 | B446: 17 | C446: بنبان | D446: Banban | E446: شارع الحكم بن عمير | G446: 3
A447: 446 | B447: 17 | C447: بنبان | D447: Banban | E447: شارع التعليم | G447: 3
A448: 447 | B448: 17 | C448: بنبان | D448: Banban | E448: شارع الحكم بن مرة | G448: 3
A449: 448 | B449: 17 | C449: بنبان | D449: Banban | E449: طريق الملك عبدالعزيز | F449: 1 | G449: 3
A450: 449 | B450: 17 | C450: بنبان | D450: Banban | E450: طريق ابي بكر الصديق | G450: 3
A451: 450 | B451: 17 | C451: بنبان | D451: Banban | E451: Mustafa Abdulaal | G451: 3
A452: 451 | B452: 17 | C452: بنبان | D452: Banban | E452: Khozain Bin Lhayan | G452: 3
A453: 452 | B453: 17 | C453: بنبان | D453: Banban | E453: https://maps.app.goo.gl/hR5FJYQVzMYBMunJ9?g_st=ic | G453: 3
A454: 453 | B454: 17 | C454: بنبان | D454: Banban | E454: https://maps.app.goo.gl/Tpgdxumnv4Gahb6d8?g_st=ic | G454: 3
A455: 454 | B455: 17 | C455: بنبان | D455: Banban | E455: https://maps.app.goo.gl/eRuvBEBsrhMkM1dQ8?g_st=ic | G455: 3
A456: 455 | B456: 17 | C456: بنبان | D456: Banban | E456: https://maps.app.goo.gl/nMY9A8BARP7e2Ww56?g_st=ic | G456: 3
A457: 456 | B457: 17 | C457: بنبان | D457: Banban | E457: https://maps.app.goo.gl/CstxBERkde4nCXm56?g_st=ic | G457: 3
...

Sheet Clean deduplicated streets
A1: ID | B1: District Number | C1: District in English | D1: Street | E1: Sampled for quality check | F1: Round | G1: Comments | H1: Groups that went to it for quality | I1: New_region
A2: 1 | B2: 1 | C2: Al Yasmeen | D2: طريق انس بن مالك | E2: 1 | F2: 1 | H2: All groups | I2: =VLOOKUP(C2, 'New Riyadh Regions'!B:C, 2, FALSE) -> North
A3: 2 | B3: 1 | C3: Al Yasmeen | D3: طريق الملك عبدالعزيز جهة اليمين | E3: 1 | F3: 1 | H3: All groups | I3: =VLOOKUP(C3, 'New Riyadh Regions'!B:C, 2, FALSE) -> North
A4: 3 | B4: 1 | C4: Al Yasmeen | D4: طريق أبي بكر الصديق جهة اليمين | E4: 1 | F4: 1 | H4: All groups | I4: =VLOOKUP(C4, 'New Riyadh Regions'!B:C, 2, FALSE) -> North
A5: 4 | B5: 1 | C5: Al Yasmeen | D5: طريق الثمامة الفرعي | E5: 1 | F5: 1 | H5: All groups | I5: =VLOOKUP(C5, 'New Riyadh Regions'!B:C, 2, FALSE) -> North
A6: 5 | B6: 1 | C6: Al Yasmeen | D6: طريق الملك فهد | E6: 1 | F6: 1 | H6: All groups | I6: =VLOOKUP(C6, 'New Riyadh Regions'!B:C, 2, FALSE) -> North
A7: 6 | B7: 1 | C7: Al Yasmeen | D7: شارع القلعة | E7: 1 | F7: 1 | H7: All groups | I7: =VLOOKUP(C7, 'New Riyadh Regions'!B:C, 2, FALSE) -> North
A8: 7 | B8: 1 | C8: Al Yasmeen | D8: شارع الفجر | E8: 1 | F8: 1 | H8: All groups | I8: =VLOOKUP(C8, 'New Riyadh Regions'!B:C, 2, FALSE) -> North
A9: 8 | B9: 1 | C9: Al Yasmeen | D9: شارع القادسية | E9: 1 | F9: 1 | H9: All groups | I9: =VLOOKUP(C9, 'New Riyadh Regions'!B:C, 2, FALSE) -> North
A10: 9 | B10: 1 | C10: Al Yasmeen | D10: شارع الأمير ناصر بن سعود بن فرحان آل سعود | E10: 1 | F10: 1 | H10: All groups | I10: =VLOOKUP(C10, 'New Riyadh Regions'!B:C, 2, FALSE) -> North
A11: 10 | B11: 1 | C11: Al Yasmeen | D11: القنا | E11: 1 | F11: 1 | H11: All groups | I11: =VLOOKUP(C11, 'New Riyadh Regions'!B:C, 2, FALSE) -> North
A12: 11 | B12: 1 | C12: Al Yasmeen | D12: الامير عبدالعزيز بن عياف | E12: 1 | F12: 1 | H12: All groups | I12: =VLOOKUP(C12, 'New Riyadh Regions'!B:C, 2, FALSE) -> North
A13: 12 | B13: 1 | C13: Al Yasmeen | D13: الخيالة | E13: 1 | F13: 1 | H13: All groups | I13: =VLOOKUP(C13, 'New Riyadh Regions'!B:C, 2, FALSE) -> North
... A418: 391 | B418: 14 | C418: Al Ghadeer | D418: النفود | E418: 1 | F418: 2 | H418: C and G | I418: =VLOOKUP(C418, 'New Riyadh Regions'!B:C, 2, FALSE) -> North
A419: 418 | B419: 17 | C419: Banban | D419: طريق صلبوخ | F419: 3 | H419: A | I419: =VLOOKUP(C419, 'New Riyadh Regions'!B:C, 2, FALSE) -> North
A420: 1215 | B420: 55 | C420: Al Mursalat | D420: الامير مقرن بن عبدالعزيز | E420: 1 | F420: 5 | H420: A | I420: =VLOOKUP(C420, 'New Riyadh Regions'!B:C, 2, FALSE) -> Center
A421: 420 | B421: 17 | C421: Banban | D421: SS21 Link | F421: 3 | H421: A | I421: =VLOOKUP(C421, 'New Riyadh Regions'!B:C, 2, FALSE) -> North
A422: 421 | B422: 17 | C422: Banban | D422: SS22 Link 2 | F422: 3 | H422: A | I422: =VLOOKUP(C422, 'New Riyadh Regions'!B:C, 2, FALSE) -> North
A423: 422 | B423: 17 | C423: Banban | D423: طريق الملك فهد | F423: 3 | H423: A | I423: =VLOOKUP(C423, 'New Riyadh Regions'!B:C, 2, FALSE) -> North
A424: 423 | B424: 17 | C424: Banban | D424: طريق الأمير محمد بن سعد بن عبدالعزيز | F424: 3 | H424: A | I424: =VLOOKUP(C424, 'New Riyadh Regions'!B:C, 2, FALSE) -> North
A425: 424 | B425: 17 | C425: Banban | D425: طريق بنبان | F425: 3 | H425: A | I425: =VLOOKUP(C425, 'New Riyadh Regions'!B:C, 2, FALSE) -> North
A426: 425 | B426: 17 | C426: Banban | D426: طريق بنبان المطار | F426: 3 | H426: A | I426: =VLOOKUP(C426, 'New Riyadh Regions'!B:C, 2, FALSE) -> North
A427: 426 | B427: 17 | C427: Banban | D427: وادي بنبان | F427: 3 | H427: A | I427: =VLOOKUP(C427, 'New Riyadh Regions'!B:C, 2, FALSE) -> North
A428: 427 | B428: 17 | C428: Banban | D428: شارع الماس | F428: 3 | H428: A | I428: =VLOOKUP(C428, 'New Riyadh Regions'!B:C, 2, FALSE) -> North
A429: 428 | B429: 17 | C429: Banban | D429: شارع خالد بن معبد | F429: 3 | H429: A | I429: =VLOOKUP(C429, 'New Riyadh Regions'!B:C, 2, FALSE) -> North
A430: 429 | B430: 17 | C430: Banban | D430: شارع الصواب | F430: 3 | H430: A | I430: =VLOOKUP(C430, 'New Riyadh Regions'!B:C, 2, FALSE) -> North
A431: 430 | B431: 17 | C431: Banban | D431: شارع الدرة | F431: 3 | H431: A | I431: =VLOOKUP(C431, 'New Riyadh Regions'!B:C, 2, FALSE) -> North
A432: 1216 | B432: 55 | C432: Al Mursalat | D432: الامير مشهور بن عبدالعزيز | E432: 1 | F432: 5 | H432: A | I432: =VLOOKUP(C432, 'New Riyadh Regions'!B:C, 2, FALSE) -> Center
A433: 432 | B433: 17 | C433: Banban | D433: شارع الحكم بن عمير | F433: 3 | H433: A | I433: =VLOOKUP(C433, 'New Riyadh Regions'!B:C, 2, FALSE) -> North
A434: 433 | B434: 17 | C434: Banban | D434: شارع التعليم | F434: 3 | H434: A | I434: =VLOOKUP(C434, 'New Riyadh Regions'!B:C, 2, FALSE) -> North
A435: 434 | B435: 17 | C435: Banban | D435: شارع الحكم بن مرة | F435: 3 | H435: A | I435: =VLOOKUP(C435, 'New Riyadh Regions'!B:C, 2, FALSE) -> North
A436: 1224 | B436: 56 | C436: Al Muruj | D436: طريق الملك فهد | E436: 1 | F436: 5 | H436: A | I436: =VLOOKUP(C436, 'New Riyadh Regions'!B:C, 2, FALSE) -> Center
A437: 436 | B437: 17 | C437: Banban | D437: طريق ابي بكر الصديق | F437: 3 | H437: A | I437: =VLOOKUP(C437, 'New Riyadh Regions'!B:C, 2, FALSE) -> North
A438: 437 | B438: 17 | C438: Banban | D438: Mustafa Abdulaal | F438: 3 | H438: A | I438: =VLOOKUP(C438, 'New Riyadh Regions'!B:C, 2, FALSE) -> North
A439: 438 | B439: 17 | C439: Banban | D439: Khozain Bin Lhayan | F439: 3 | H439: A | I439: =VLOOKUP(C439, 'New Riyadh Regions'!B:C, 2, FALSE) -> North
A440: 439 | B440: 17 | C440: Banban | D440: https://maps.app.goo.gl/hR5FJYQVzMYBMunJ9?g_st=ic | F440: 3 | H440: A | I440: =VLOOKUP(C440, 'New Riyadh Regions'!B:C, 2, FALSE) -> North
A441: 440 | B441: 17 | C441: Banban | D441: https://maps.app.goo.gl/Tpgdxumnv4Gahb6d8?g_st=ic | F441: 3 | H441: A | I441: =VLOOKUP(C441, 'New Riyadh Regions'!B:C, 2, FALSE) -> North
A442: 441 | B442: 17 | C442: Banban | D442: https://maps.app.goo.gl/eRuvBEBsrhMkM1dQ8?g_st=ic | F442: 3 | H442: A | I442: =VLOOKUP(C442, 'New Riyadh Regions'!B:C, 2, FALSE) -> North
A443: 442 | B443: 17 | C443: Banban | D443: https://maps.app.goo.gl/nMY9A8BARP7e2Ww56?g_st=ic | F443: 3 | H443: A | I443: =VLOOKUP(C443, 'New Riyadh Regions'!B:C, 2, FALSE) -> North
A444: 443 | B444: 17 | C444: Banban | D444: https://maps.app.goo.gl/CstxBERkde4nCXm56?g_st=ic | F444: 3 | H444: A | I444: =VLOOKUP(C444, 'New Riyadh Regions'!B:C, 2, FALSE) -> North
...
